<?xml version="1.0" encoding="utf-8"?>
<!-- This URDF was automatically created by SolidWorks to URDF Exporter! Originally created by Stephen Brawner (brawner@gmail.com) 
     Commit Version: 1.6.0-4-g7f85cfe  Build Version: 1.6.7995.38578
     For more information, please see http://wiki.ros.org/sw_urdf_exporter -->
<robot
  name="SIAT">
  <link
    name="base_link">
    <inertial>
      <origin
        xyz="0.32283 0.0054798 0.19053"
        rpy="0 0 0" />
      <mass
        value="11.483" />
      <inertia
        ixx="0.10681"
        ixy="-0.007053"
        ixz="-0.00047763"
        iyy="0.1025"
        iyz="6.0356E-05"
        izz="0.12332" />
    </inertial>
    <visual>
      <origin
        xyz="0 0 0"
        rpy="0 0 0" />
      <geometry>
        <mesh
          filename="package://SIAT/meshes/base_link.STL" />
      </geometry>
      <material
        name="">
        <color
          rgba="0.75294 0.75294 0.75294 1" />
      </material>
    </visual>
    <collision>
      <origin
        xyz="0 0 0"
        rpy="0 0 0" />
      <geometry>
        <mesh
          filename="package://SIAT/meshes/base_link.STL" />
      </geometry>
    </collision>
  </link>
  <link
    name="r_1">
    <inertial>
      <origin
        xyz="0.079905 -0.0081434 0.026887"
        rpy="0 0 0" />
      <mass
        value="2.8322" />
      <inertia
        ixx="0.0025127"
        ixy="0.00039573"
        ixz="-7.1211E-05"
        iyy="0.0065445"
        iyz="-5.6669E-05"
        izz="0.0072351" />
    </inertial>
    <visual>
      <origin
        xyz="0 0 0"
        rpy="0 0 0" />
      <geometry>
        <mesh
          filename="package://SIAT/meshes/r_1.STL" />
      </geometry>
      <material
        name="">
        <color
          rgba="0.5451 0.61569 0.85882 1" />
      </material>
    </visual>
  </link>
  <joint
    name="joint_r_1"
    type="revolute">
    <origin
      xyz="0 0.105 0"
      rpy="1.5708 0 1.5708" />
    <parent
      link="base_link" />
    <child
      link="r_1" />
    <axis
      xyz="0 0 -1" />
    <limit
      lower="-0.5236"
      upper="0.69813"
      effort="300"
      velocity="10" />
  </joint>
  <link
    name="r_2">
    <inertial>
      <origin
        xyz="0.11644 0.0055321 0.028381"
        rpy="0 0 0" />
      <mass
        value="4.2266" />
      <inertia
        ixx="0.0044533"
        ixy="7.1351E-05"
        ixz="-8.8635E-05"
        iyy="0.012089"
        iyz="-2.3903E-05"
        izz="0.012074" />
    </inertial>
    <visual>
      <origin
        xyz="0 0 0"
        rpy="0 0 0" />
      <geometry>
        <mesh
          filename="package://SIAT/meshes/r_2.STL" />
      </geometry>
      <material
        name="">
        <color
          rgba="0.92941 0.76863 0.67059 1" />
      </material>
    </visual>

  </link>
  <joint
    name="joint_r_2"
    type="revolute">
    <origin
      xyz="0.159 0 0"
      rpy="-1.5708 -1.5708 0" />
    <parent
      link="r_1" />
    <child
      link="r_2" />
    <axis
      xyz="0 0 -1" />
    <limit
      lower="-0.38397"
      upper="0.5236"
      effort="300"
      velocity="10" />
  </joint>
  <link
    name="r_3">
    <inertial>
      <origin
        xyz="0.22207 0.00020696 -0.026349"
        rpy="0 0 0" />
      <mass
        value="11.84" />
      <inertia
        ixx="0.014461"
        ixy="-0.00099269"
        ixz="-0.0049046"
        iyy="0.1909"
        iyz="0.00030176"
        izz="0.20128" />
    </inertial>
    <visual>
      <origin
        xyz="0 0 0"
        rpy="0 0 0" />
      <geometry>
        <mesh
          filename="package://SIAT/meshes/r_3.STL" />
      </geometry>
      <material
        name="">
        <color
          rgba="0.8902 0.71765 0.58824 1" />
      </material>
    </visual>

  </link>
  <joint
    name="joint_r_3"
    type="revolute">
    <origin
      xyz="0.205 0 0"
      rpy="-1.5708 1.5708 0" />
    <parent
      link="r_2" />
    <child
      link="r_3" />
    <axis
      xyz="0 0 1" />
    <limit
      lower="-0.69813"
      upper="0.2618"
      effort="300"
      velocity="10" />
  </joint>
  <link
    name="r_4">
    <inertial>
      <origin
        xyz="0.12085 0.011457 -0.024406"
        rpy="0 0 0" />
      <mass
        value="3.321" />
      <inertia
        ixx="0.0027063"
        ixy="-0.00041011"
        ixz="-0.00092136"
        iyy="0.013003"
        iyz="-7.9616E-05"
        izz="0.012137" />
    </inertial>
    <visual>
      <origin
        xyz="0 0 0"
        rpy="0 0 0" />
      <geometry>
        <mesh
          filename="package://SIAT/meshes/r_4.STL" />
      </geometry>
      <material
        name="">
        <color
          rgba="0.75294 1 1 1" />
      </material>
    </visual>

  </link>
  <joint
    name="joint_r_4"
    type="revolute">
    <origin
      xyz="0.44 0 0"
      rpy="0 0 0" />
    <parent
      link="r_3" />
    <child
      link="r_4" />
    <axis
      xyz="0 0 1" />
    <limit
      lower="-0.052399"
      upper="1.2217"
      effort="300"
      velocity="10" />
  </joint>
  <link
    name="r_5">
    <inertial>
      <origin
        xyz="-0.000208 -0.015363 -0.011661"
        rpy="0 0 0" />
      <mass
        value="0.11725" />
      <inertia
        ixx="3.2429E-05"
        ixy="3.1988E-10"
        ixz="6.8398E-11"
        iyy="2.1488E-05"
        iyz="5.1115E-16"
        izz="2.1496E-05" />
    </inertial>
    <visual>
      <origin
        xyz="0 0 0"
        rpy="0 0 0" />
      <geometry>
        <mesh
          filename="package://SIAT/meshes/r_5.STL" />
      </geometry>
      <material
        name="">
        <color
          rgba="0.92157 0.88235 0.64314 1" />
      </material>
    </visual>

  </link>
  <joint
    name="joint_r_5"
    type="revolute">
    <origin
      xyz="0.4 0 0"
      rpy="0 0 0" />
    <parent
      link="r_4" />
    <child
      link="r_5" />
    <axis
      xyz="0 0 1" />
    <limit
      lower="-0.62831"
      upper="0.69813"
      effort="300"
      velocity="10" />
  </joint>
  <link
    name="r_6">
    <inertial>
      <origin
        xyz="0.094957 -0.049767 0.038082"
        rpy="0 0 0" />
      <mass
        value="1.4525" />
      <inertia
        ixx="0.0098192"
        ixy="7.9321E-05"
        ixz="-2.2112E-05"
        iyy="0.0068454"
        iyz="0.0002905"
        izz="0.0033135" />
    </inertial>
    <visual>
      <origin
        xyz="0 0 0"
        rpy="0 0 0" />
      <geometry>
        <mesh
          filename="package://SIAT/meshes/r_6.STL" />
      </geometry>
      <material
        name="">
        <color
          rgba="0.75294 0.75294 0.75294 1" />
      </material>
    </visual>
    <collision>
      <origin
        xyz="0 0 0"
        rpy="0 0 0" />
      <geometry>
        <mesh
          filename="package://SIAT/meshes/r_6.STL" />
      </geometry>
    </collision>
  </link>
  <joint
    name="joint_r_6"
    type="revolute">
    <origin
      xyz="0 0 -0.0275"
      rpy="1.5708 0 0" />
    <parent
      link="r_5" />
    <child
      link="r_6" />
    <axis
      xyz="0 0 -1" />
    <limit
      lower="-0.43633"
      upper="0.34907"
      effort="300"
      velocity="10" />
  </joint>
  <link
    name="l_1">
    <inertial>
      <origin
        xyz="0.08002 0.0081433 0.026963"
        rpy="0 0 0" />
      <mass
        value="2.8322" />
      <inertia
        ixx="0.0025118"
        ixy="-0.00039481"
        ixz="-7.0805E-05"
        iyy="0.0065445"
        iyz="5.728E-05"
        izz="0.007236" />
    </inertial>
    <visual>
      <origin
        xyz="0 0 0"
        rpy="0 0 0" />
      <geometry>
        <mesh
          filename="package://SIAT/meshes/l_1.STL" />
      </geometry>
      <material
        name="">
        <color
          rgba="0.5451 0.61569 0.85882 1" />
      </material>
    </visual>
  </link>
  <joint
    name="joint_l_1"
    type="revolute">
    <origin
      xyz="0 -0.105 0"
      rpy="-1.5708 0 -1.5708" />
    <parent
      link="base_link" />
    <child
      link="l_1" />
    <axis
      xyz="0 0 -1" />
    <limit
      lower="-0.69813"
      upper="0.5236"
      effort="300"
      velocity="10" />
  </joint>
  <link
    name="l_2">
    <inertial>
      <origin
        xyz="0.11644 -0.0055321 0.028383"
        rpy="0 0 0" />
      <mass
        value="4.2266" />
      <inertia
        ixx="0.0044012"
        ixy="-7.2688E-05"
        ixz="-0.00010249"
        iyy="0.012089"
        iyz="2.2164E-05"
        izz="0.012126" />
    </inertial>
    <visual>
      <origin
        xyz="0 0 0"
        rpy="0 0 0" />
      <geometry>
        <mesh
          filename="package://SIAT/meshes/l_2.STL" />
      </geometry>
      <material
        name="">
        <color
          rgba="0.64706 0.61961 0.58824 1" />
      </material>
    </visual>
  </link>
  <joint
    name="joint_l_2"
    type="revolute">
    <origin
      xyz="0.159 0 0"
      rpy="1.5708 -1.5708 0" />
    <parent
      link="l_1" />
    <child
      link="l_2" />
    <axis
      xyz="0 0 -1" />
    <limit
      lower="-0.5236"
      upper="0.38397"
      effort="300"
      velocity="10" />
  </joint>
  <link
    name="l_3">
    <inertial>
      <origin
        xyz="0.22192 0.00017641 0.030643"
        rpy="0 0 0" />
      <mass
        value="11.835" />
      <inertia
        ixx="0.014422"
        ixy="-0.00098286"
        ixz="0.0049082"
        iyy="0.19094"
        iyz="-0.00029818"
        izz="0.20127" />
    </inertial>
    <visual>
      <origin
        xyz="0 0 0"
        rpy="0 0 0" />
      <geometry>
        <mesh
          filename="package://SIAT/meshes/l_3.STL" />
      </geometry>
      <material
        name="">
        <color
          rgba="0.8902 0.71765 0.58824 1" />
      </material>
    </visual>

  </link>
  <joint
    name="joint_l_3"
    type="revolute">
    <origin
      xyz="0.205 -0.0042446 0"
      rpy="-1.5708 1.5708 0" />
    <parent
      link="l_2" />
    <child
      link="l_3" />
    <axis
      xyz="0 0 -1" />
    <limit
      lower="-0.69813"
      upper="0.2618"
      effort="300"
      velocity="10" />
  </joint>
  <link
    name="l_4">
    <inertial>
      <origin
        xyz="0.12027 0.011268 0.028835"
        rpy="0 0 0" />
      <mass
        value="3.3252" />
      <inertia
        ixx="0.0027061"
        ixy="-0.00041124"
        ixz="0.00092324"
        iyy="0.013004"
        iyz="7.962E-05"
        izz="0.012137" />
    </inertial>
    <visual>
      <origin
        xyz="0 0 0"
        rpy="0 0 0" />
      <geometry>
        <mesh
          filename="package://SIAT/meshes/l_4.STL" />
      </geometry>
      <material
        name="">
        <color
          rgba="0.64706 0.61961 0.58824 1" />
      </material>
    </visual>

  </link>
  <joint
    name="joint_l_4"
    type="revolute">
    <origin
      xyz="0.44 0 0"
      rpy="0 0 0" />
    <parent
      link="l_3" />
    <child
      link="l_4" />
    <axis
      xyz="0 0 -1" />
    <limit
      lower="-0.052399"
      upper="1.2217"
      effort="300"
      velocity="10" />
  </joint>
  <link
    name="l_5">
    <inertial>
      <origin
        xyz="-6.4804E-11 -0.015497 0.016136"
        rpy="0 0 0" />
      <mass
        value="0.11805" />
      <inertia
        ixx="3.2455E-05"
        ixy="-3.133E-10"
        ixz="3.7122E-10"
        iyy="2.1552E-05"
        iyz="-1.5081E-15"
        izz="2.1516E-05" />
    </inertial>
    <visual>
      <origin
        xyz="0 0 0"
        rpy="0 0 0" />
      <geometry>
        <mesh
          filename="package://SIAT/meshes/l_5.STL" />
      </geometry>
      <material
        name="">
        <color
          rgba="0.75686 0.76863 0.75294 1" />
      </material>
    </visual>

  </link>
  <joint
    name="joint_l_5"
    type="revolute">
    <origin
      xyz="0.4 0 0"
      rpy="0 0 0" />
    <parent
      link="l_4" />
    <child
      link="l_5" />
    <axis
      xyz="0 0 -1" />
    <limit
      lower="-0.62831"
      upper="0.69813"
      effort="300"
      velocity="10" />
  </joint>
  <link
    name="l_6">
    <inertial>
      <origin
        xyz="0.049726 -0.094974 0.038045"
        rpy="0 0 0" />
      <mass
        value="1.4527" />
      <inertia
        ixx="0.006844"
        ixy="7.9121E-05"
        ixz="-0.00029087"
        iyy="0.0098206"
        iyz="2.2749E-05"
        izz="0.003315" />
    </inertial>
    <visual>
      <origin
        xyz="0 0 0"
        rpy="0 0 0" />
      <geometry>
        <mesh
          filename="package://SIAT/meshes/l_6.STL" />
      </geometry>
      <material
        name="">
        <color
          rgba="0.75294 0.75294 0.75294 1" />
      </material>
    </visual>
    <collision>
      <origin
        xyz="0 0 0"
        rpy="0 0 0" />
      <geometry>
        <mesh
          filename="package://SIAT/meshes/l_6.STL" />
      </geometry>
    </collision>
  </link>
  <joint
    name="joint_l_6"
    type="revolute">
    <origin
      xyz="0 0 0.031745"
      rpy="1.5708 -1.5708 0" />
    <parent
      link="l_5" />
    <child
      link="l_6" />
    <axis
      xyz="0 0 1" />
    <limit
      lower="-0.34907"
      upper="0.43633"
      effort="300"
      velocity="10" />
  </joint>
</robot>
