<?xml version="1.0" encoding="utf-8"?>
<!-- This URDF was automatically created by SolidWorks to URDF Exporter! Originally created by Stephen Brawner (brawner@gmail.com) 
     Commit Version: 1.6.0-4-g7f85cfe  Build Version: 1.6.7995.38578
     For more information, please see http://wiki.ros.org/sw_urdf_exporter -->
<robot
  name="zongzhuangURDF">
  <link
    name="base_link">
    <inertial>
      <origin
        xyz="0.108508325586204 0.0146837974591004 -0.319193198969718"
        rpy="0 0 0" />
      <mass
        value="9.42178207273787" />
      <inertia
        ixx="0.102465221562928"
        ixy="-0.00646016637771504"
        ixz="-0.000192985912922859"
        iyy="0.111182856145114"
        iyz="-7.17962851922865E-07"
        izz="0.125080945514604" />
    </inertial>
    <visual>
      <origin
        xyz="0 0 0"
        rpy="0 0 0" />
      <geometry>
        <mesh
          filename="../zongzhuangURDF/meshes/base_link.stl" />
      </geometry>
      <material
        name="">
        <color
          rgba="0.647058823529412 0.619607843137255 0.588235294117647 1" />
      </material>
    </visual>
    <collision>
      <origin
        xyz="0 0 0"
        rpy="0 0 0" />
      <geometry>
        <mesh
          filename="../zongzhuangURDF/meshes/base_link.stl" />
      </geometry>
    </collision>
  </link>
  <link
    name="R1">
    <inertial>
      <origin
        xyz="-0.00554949522233184 0.000114401998525748 -0.0979074940082722"
        rpy="0 0 0" />
      <mass
        value="1.51779481990465" />
      <inertia
        ixx="0.00245800943956294"
        ixy="-4.41521773761165E-07"
        ixz="-4.63899441448868E-05"
        iyy="0.00236263395755816"
        iyz="5.24184346522512E-07"
        izz="0.00336403859220055" />
    </inertial>
    <visual>
      <origin
        xyz="0 0 0"
        rpy="0 0 0" />
      <geometry>
        <mesh
          filename="../zongzhuangURDF/meshes/R1.stl" />
      </geometry>
      <material
        name="">
        <color
          rgba="0.203921568627451 0.203921568627451 0.203921568627451 1" />
      </material>
    </visual>
    <collision>
      <origin
        xyz="0 0 0"
        rpy="0 0 0" />
      <geometry>
        <mesh
          filename="../zongzhuangURDF/meshes/R1.stl" />
      </geometry>
    </collision>
  </link>
  <joint
    name="r1"
    type="revolute">
    <origin
      xyz="-0.019297 -0.109 -0.50753"
      rpy="0 1.5708 0" />
    <parent
      link="base_link" />
    <child
      link="R1" />
    <axis
      xyz="0 0 -1" />
    <limit
      lower="0"
      upper="100"
      effort="100"
      velocity="100" />
  </joint>
  <link
    name="R2">
    <inertial>
      <origin
        xyz="0.250026181846938 -0.136608711068529 -0.0645080764672321"
        rpy="0 0 0" />
      <mass
        value="3.38765409362828" />
      <inertia
        ixx="0.00481452148453492"
        ixy="0.000202464946759136"
        ixz="-1.33630331746647E-06"
        iyy="0.00726017644456554"
        iyz="-1.03783472405917E-05"
        izz="0.00756291577865967" />
    </inertial>
    <visual>
      <origin
        xyz="0 0 0"
        rpy="0 0 0" />
      <geometry>
        <mesh
          filename="../zongzhuangURDF/meshes/R2.stl" />
      </geometry>
      <material
        name="">
        <color
          rgba="0.203921568627451 0.203921568627451 0.203921568627451 1" />
      </material>
    </visual>
    <collision>
      <origin
        xyz="0 0 0"
        rpy="0 0 0" />
      <geometry>
        <mesh
          filename="../zongzhuangURDF/meshes/R2.stl" />
      </geometry>
    </collision>
  </link>
  <joint
    name="r2"
    type="revolute">
    <origin
      xyz="-0.074 0.004 -0.18726"
      rpy="3.1416 -1.5708 0" />
    <parent
      link="R1" />
    <child
      link="R2" />
    <axis
      xyz="0 0 -1" />
    <limit
      lower="0"
      upper="100"
      effort="100"
      velocity="100" />
  </joint>
  <link
    name="R3">
    <inertial>
      <origin
        xyz="0.00428821051037809 -0.210045840770061 -0.024337506823458"
        rpy="0 0 0" />
      <mass
        value="1.55569553643649" />
      <inertia
        ixx="0.00470363819886716"
        ixy="-5.64656251093002E-05"
        ixz="4.81096129758025E-05"
        iyy="0.00288796096586703"
        iyz="-5.66863338663946E-06"
        izz="0.00529102208273278" />
    </inertial>
    <visual>
      <origin
        xyz="0 0 0"
        rpy="0 0 0" />
      <geometry>
        <mesh
          filename="../zongzhuangURDF/meshes/R3.stl" />
      </geometry>
      <material
        name="">
        <color
          rgba="0.203921568627451 0.203921568627451 0.203921568627451 1" />
      </material>
    </visual>
    <collision>
      <origin
        xyz="0 0 0"
        rpy="0 0 0" />
      <geometry>
        <mesh
          filename="../zongzhuangURDF/meshes/R3.stl" />
      </geometry>
    </collision>
  </link>
  <joint
    name="r3"
    type="revolute">
    <origin
      xyz="0.35806 -0.1057 -0.073552"
      rpy="1.5708 0 3.1416" />
    <parent
      link="R2" />
    <child
      link="R3" />
    <axis
      xyz="0 0 -1" />
    <limit
      lower="0"
      upper="100"
      effort="100"
      velocity="100" />
  </joint>
  <link
    name="R4">
    <inertial>
      <origin
        xyz="0.00253089925915702 -0.327230469038829 -0.0436394431934457"
        rpy="0 0 0" />
      <mass
        value="2.71063429202876" />
      <inertia
        ixx="0.0203006815060119"
        ixy="7.65976712943799E-05"
        ixz="3.65709504636148E-06"
        iyy="0.003277615843604"
        iyz="-0.000858028173816362"
        izz="0.0208829866242641" />
    </inertial>
    <visual>
      <origin
        xyz="0 0 0"
        rpy="0 0 0" />
      <geometry>
        <mesh
          filename="../zongzhuangURDF/meshes/R4.stl" />
      </geometry>
      <material
        name="">
        <color
          rgba="0.203921568627451 0.203921568627451 0.203921568627451 1" />
      </material>
    </visual>
    <collision>
      <origin
        xyz="0 0 0"
        rpy="0 0 0" />
      <geometry>
        <mesh
          filename="../zongzhuangURDF/meshes/R4.stl" />
      </geometry>
    </collision>
  </link>
  <joint
    name="r4"
    type="revolute">
    <origin
      xyz="5.9136E-05 -0.18045 0.0007"
      rpy="0 0 0" />
    <parent
      link="R3" />
    <child
      link="R4" />
    <axis
      xyz="0 0 -1" />
    <limit
      lower="0"
      upper="100"
      effort="100"
      velocity="100" />
  </joint>
  <link
    name="R5">
    <inertial>
      <origin
        xyz="-0.0404638812825985 -0.474230643441424 0.064948016318006"
        rpy="0 0 0" />
      <mass
        value="2.75166048062153" />
      <inertia
        ixx="0.00822262902967522"
        ixy="-5.18405343958851E-05"
        ixz="0.000564288004150448"
        iyy="0.0184077002179176"
        iyz="0.000106838646470046"
        izz="0.0129901003888962" />
    </inertial>
    <visual>
      <origin
        xyz="0 0 0"
        rpy="0 0 0" />
      <geometry>
        <mesh
          filename="../zongzhuangURDF/meshes/R5.stl" />
      </geometry>
      <material
        name="">
        <color
          rgba="0.203921568627451 0.203921568627451 0.203921568627451 1" />
      </material>
    </visual>
    <collision>
      <origin
        xyz="0 0 0"
        rpy="0 0 0" />
      <geometry>
        <mesh
          filename="../zongzhuangURDF/meshes/R5.stl" />
      </geometry>
    </collision>
  </link>
  <joint
    name="r5"
    type="revolute">
    <origin
      xyz="0 -0.259 -0.0305"
      rpy="0 0 0" />
    <parent
      link="R4" />
    <child
      link="R5" />
    <axis
      xyz="0 0 -1" />
    <limit
      lower="0"
      upper="100"
      effort="100"
      velocity="100" />
  </joint>
  <link
    name="R6">
    <inertial>
      <origin
        xyz="0.375757483545611 0.0588554601692003 0.0438139202102486"
        rpy="0 0 0" />
      <mass
        value="2.58090518563935" />
      <inertia
        ixx="0.0183265248471455"
        ixy="-0.000110484792794042"
        ixz="-5.18717858420123E-05"
        iyy="0.0121030695008154"
        iyz="-0.000563756384745253"
        izz="0.00747330630025743" />
    </inertial>
    <visual>
      <origin
        xyz="0 0 0"
        rpy="0 0 0" />
      <geometry>
        <mesh
          filename="../zongzhuangURDF/meshes/R6.stl" />
      </geometry>
      <material
        name="">
        <color
          rgba="0.203921568627451 0.203921568627451 0.203921568627451 1" />
      </material>
    </visual>
    <collision>
      <origin
        xyz="0 0 0"
        rpy="0 0 0" />
      <geometry>
        <mesh
          filename="../zongzhuangURDF/meshes/R6.stl" />
      </geometry>
    </collision>
  </link>
  <joint
    name="r6"
    type="revolute">
    <origin
      xyz="0.0065 -0.37 -0.0265"
      rpy="1.5708 0 -1.5708" />
    <parent
      link="R4" />
    <child
      link="R6" />
    <axis
      xyz="0 0 -1" />
    <limit
      lower="0"
      upper="100"
      effort="100"
      velocity="100" />
  </joint>
  <link
    name="L1">
    <inertial>
      <origin
        xyz="0.000120977453167082 0.00623284848702421 -0.09845242410647"
        rpy="0 0 0" />
      <mass
        value="1.53313730127232" />
      <inertia
        ixx="0.00236330403950826"
        ixy="5.59909379398475E-07"
        ixz="-2.53332631477571E-07"
        iyy="0.00245816304605807"
        iyz="4.63507523677144E-05"
        izz="0.00336463859498981" />
    </inertial>
    <visual>
      <origin
        xyz="0 0 0"
        rpy="0 0 0" />
      <geometry>
        <mesh
          filename="../zongzhuangURDF/meshes/L1.stl" />
      </geometry>
      <material
        name="">
        <color
          rgba="0.203921568627451 0.203921568627451 0.203921568627451 1" />
      </material>
    </visual>
    <collision>
      <origin
        xyz="0 0 0"
        rpy="0 0 0" />
      <geometry>
        <mesh
          filename="../zongzhuangURDF/meshes/L1.stl" />
      </geometry>
    </collision>
  </link>
  <joint
    name="l1"
    type="revolute">
    <origin
      xyz="-0.019297 0.109 -0.50753"
      rpy="1.5708 -0.0015844 1.5708" />
    <parent
      link="base_link" />
    <child
      link="L1" />
    <axis
      xyz="0 0 -1" />
    <limit
      lower="0"
      upper="100"
      effort="100"
      velocity="100" />
  </joint>
  <link
    name="L2">
    <inertial>
      <origin
        xyz="0.260220119735123 0.133425223537314 -0.0678508609941246"
        rpy="0 0 0" />
      <mass
        value="3.84440599266414" />
      <inertia
        ixx="0.00543440493172141"
        ixy="-0.000195237434216319"
        ixz="-1.35424363791128E-08"
        iyy="0.00846961411894216"
        iyz="7.28738195188599E-06"
        izz="0.00817415948554993" />
    </inertial>
    <visual>
      <origin
        xyz="0 0 0"
        rpy="0 0 0" />
      <geometry>
        <mesh
          filename="../zongzhuangURDF/meshes/L2.stl" />
      </geometry>
      <material
        name="">
        <color
          rgba="0.203921568627451 0.203921568627451 0.203921568627451 1" />
      </material>
    </visual>
    <collision>
      <origin
        xyz="0 0 0"
        rpy="0 0 0" />
      <geometry>
        <mesh
          filename="../zongzhuangURDF/meshes/L2.stl" />
      </geometry>
    </collision>
  </link>
  <joint
    name="l2"
    type="revolute">
    <origin
      xyz="0.0021212 0.076497 -0.18726"
      rpy="1.5692 -1.5708 0" />
    <parent
      link="L1" />
    <child
      link="L2" />
    <axis
      xyz="0 0 -1" />
    <limit
      lower="0"
      upper="100"
      effort="100"
      velocity="100" />
  </joint>
  <link
    name="L3">
    <inertial>
      <origin
        xyz="-0.0086765166292917 -0.209234579610393 -0.020031505445948"
        rpy="0 0 0" />
      <mass
        value="1.56561550782437" />
      <inertia
        ixx="0.00471790185337092"
        ixy="-5.66930870728927E-06"
        ixz="-5.07696014416872E-05"
        iyy="0.00289352559749829"
        iyz="-1.44620312820952E-06"
        izz="0.00531080605274946" />
    </inertial>
    <visual>
      <origin
        xyz="0 0 0"
        rpy="0 0 0" />
      <geometry>
        <mesh
          filename="../zongzhuangURDF/meshes/L3.stl" />
      </geometry>
      <material
        name="">
        <color
          rgba="0.203921568627451 0.203921568627451 0.203921568627451 1" />
      </material>
    </visual>
    <collision>
      <origin
        xyz="0 0 0"
        rpy="0 0 0" />
      <geometry>
        <mesh
          filename="../zongzhuangURDF/meshes/L3.stl" />
      </geometry>
    </collision>
  </link>
  <joint
    name="l3"
    type="revolute">
    <origin
      xyz="0.358 0.104 -0.0765"
      rpy="1.5708 0 0" />
    <parent
      link="L2" />
    <child
      link="L3" />
    <axis
      xyz="0 0 -1" />
    <limit
      lower="0"
      upper="100"
      effort="100"
      velocity="100" />
  </joint>
  <link
    name="L4">
    <inertial>
      <origin
        xyz="-0.00543383778259865 -0.326825615989976 -0.0299481233235028"
        rpy="0 0 0" />
      <mass
        value="2.69750095123579" />
      <inertia
        ixx="0.0202801145052485"
        ixy="-1.22437631229925E-05"
        ixz="-2.14490644502399E-06"
        iyy="0.00327547819847755"
        iyz="-0.000856231701877635"
        izz="0.020874009282608" />
    </inertial>
    <visual>
      <origin
        xyz="0 0 0"
        rpy="0 0 0" />
      <geometry>
        <mesh
          filename="../zongzhuangURDF/meshes/L4.stl" />
      </geometry>
      <material
        name="">
        <color
          rgba="0.203921568627451 0.203921568627451 0.203921568627451 1" />
      </material>
    </visual>
    <collision>
      <origin
        xyz="0 0 0"
        rpy="0 0 0" />
      <geometry>
        <mesh
          filename="../zongzhuangURDF/meshes/L4.stl" />
      </geometry>
    </collision>
  </link>
  <joint
    name="l4"
    type="revolute">
    <origin
      xyz="0 -0.18 0.005"
      rpy="0 0 0" />
    <parent
      link="L3" />
    <child
      link="L4" />
    <axis
      xyz="0 0 -1" />
    <limit
      lower="0"
      upper="100"
      effort="100"
      velocity="100" />
  </joint>
  <link
    name="L5">
    <inertial>
      <origin
        xyz="0.0406329975769811 -0.477251165809707 0.0843489792957395"
        rpy="0 0 0" />
      <mass
        value="2.63452067148198" />
      <inertia
        ixx="0.00817665541720397"
        ixy="5.19107810893716E-05"
        ixz="-0.000564390358997708"
        iyy="0.0183590739915058"
        iyz="0.00010679170661847"
        izz="0.0129444297415646" />
    </inertial>
    <visual>
      <origin
        xyz="0 0 0"
        rpy="0 0 0" />
      <geometry>
        <mesh
          filename="../zongzhuangURDF/meshes/L5.stl" />
      </geometry>
      <material
        name="">
        <color
          rgba="0.203921568627451 0.203921568627451 0.203921568627451 1" />
      </material>
    </visual>
    <collision>
      <origin
        xyz="0 0 0"
        rpy="0 0 0" />
      <geometry>
        <mesh
          filename="../zongzhuangURDF/meshes/L5.stl" />
      </geometry>
    </collision>
  </link>
  <joint
    name="l5"
    type="revolute">
    <origin
      xyz="0 -0.26 -0.0265"
      rpy="0 0 0" />
    <parent
      link="L4" />
    <child
      link="L5" />
    <axis
      xyz="0 0 -1" />
    <limit
      lower="0"
      upper="100"
      effort="100"
      velocity="100" />
  </joint>
  <link
    name="L6">
    <inertial>
      <origin
        xyz="0.373646379224035 -0.0580488190895495 0.0438631935207944"
        rpy="0 0 0" />
      <mass
        value="2.48766209053791" />
      <inertia
        ixx="0.0181911781959691"
        ixy="0.000110326517362554"
        ixz="-5.19918769057744E-05"
        iyy="0.0120313369343794"
        iyz="0.000563808928071704"
        izz="0.00740102207580199" />
    </inertial>
    <visual>
      <origin
        xyz="0 0 0"
        rpy="0 0 0" />
      <geometry>
        <mesh
          filename="../zongzhuangURDF/meshes/L6.stl" />
      </geometry>
      <material
        name="">
        <color
          rgba="0.203921568627451 0.203921568627451 0.203921568627451 1" />
      </material>
    </visual>
    <collision>
      <origin
        xyz="0 0 0"
        rpy="0 0 0" />
      <geometry>
        <mesh
          filename="../zongzhuangURDF/meshes/L6.stl" />
      </geometry>
    </collision>
  </link>
  <joint
    name="l6"
    type="revolute">
    <origin
      xyz="-0.0092312 -0.36983 -0.0068141"
      rpy="-1.5708 0 -1.5708" />
    <parent
      link="L4" />
    <child
      link="L6" />
    <axis
      xyz="0 0 -1" />
    <limit
      lower="0"
      upper="100"
      effort="100"
      velocity="100" />
  </joint>
</robot>
