<?xml version="1.0" ?>
<!-- This URDF was automatically created by SolidWorks to URDF Exporter! Originally created by Stephen Brawner (brawner@gmail.com) 
     Commit Version: 1.6.0-4-g7f85cfe  Build Version: 1.6.7995.38578
     For more information, please see http://wiki.ros.org/sw_urdf_exporter -->
<robot name="lm2">
  <link
    name="base_link">
    <inertial>
      <origin
        xyz="1.1615E-05 -0.028103 -0.09801"
        rpy="0 0 0" />
      <mass
        value="0.68409" />
      <inertia
        ixx="0.0015536"
        ixy="2.2725E-07"
        ixz="2.6547E-06"
        iyy="0.0012184"
        iyz="1.2457E-07"
        izz="0.0011556" />
    </inertial>
    <visual>
      <origin
        xyz="0 0 0"
        rpy="0 0 0" />
      <geometry>
        <mesh
          filename="../meshes/base_link.stl" />
      </geometry>
      <material
        name="">
        <color
          rgba="1 1 1 1" />
      </material>
    </visual>
    <collision>
      <origin
        xyz="0 0 0"
        rpy="0 0 0" />
      <geometry>
        <sphere radius="0.25"/>
      </geometry>
    </collision>
  </link>
  <link
    name="Link1">
    <inertial>
      <origin
        xyz="5.9674E-15 0.71375 -0.0039257"
        rpy="0 0 0" />
      <mass
        value="1.4782" />
      <inertia
        ixx="0.07995"
        ixy="-2.6427E-17"
        ixz="8.0462E-20"
        iyy="0.0021232"
        iyz="-1.9811E-18"
        izz="0.07964" />
    </inertial>
    <visual>
      <origin
        xyz="0 0 0"
        rpy="0 0 0" />
      <geometry>
        <mesh
          filename="../lm2/meshes/Link1.stl" />
      </geometry>
      <material
        name="">
        <color
          rgba="1 1 1 1" />
      </material>
    </visual>
    <collision>
      <origin
        xyz="0 0 0"
        rpy="0 0 0" />
      <geometry>
        <mesh
          filename="../lm2/meshes/Link1.stl" />
      </geometry>
    </collision>
  </link>
  <joint
    name="Joint1"
    type="revolute">
    <origin
      xyz="0 0.017 -0.15"
      rpy="-1.5708 -0.20153 0" />
    <parent
      link="base_link" />
    <child
      link="Link1" />
    <axis
      xyz="0 0 -1" />
    <limit
      lower="0"
      upper="100"
      effort="100"
      velocity="100" />
  </joint>
</robot>