<?xml version="1.0" encoding="utf-8"?>
<!-- This URDF was automatically created by SolidWorks to URDF Exporter! Originally created by Stephen Brawner (brawner@gmail.com) 
     Commit Version: 1.6.0-4-g7f85cfe  Build Version: 1.6.7995.38578
     For more information, please see http://wiki.ros.org/sw_urdf_exporter -->
<robot
  name="arm3">
  <link
    name="base_link">
    <inertial>
      <origin
        xyz="0 0 0.0001344"
        rpy="0 0 0" />
      <mass
        value="17.735" />
      <inertia
        ixx="0.18033"
        ixy="1.3878E-17"
        ixz="3.1561E-18"
        iyy="0.18033"
        iyz="9.2658E-19"
        izz="0.35315" />
    </inertial>
    <visual>
      <origin
        xyz="0 0 0"
        rpy="0 0 0" />
      <geometry>
        <mesh
          filename="package://arm3/meshes/base_link.STL" />
      </geometry>
      <material
        name="">
        <color
          rgba="0.89804 0.91765 0.92941 1" />
      </material>
    </visual>
    <collision>
      <origin
        xyz="0 0 0"
        rpy="0 0 0" />
      <geometry>
        <mesh
          filename="package://arm3/meshes/base_link.STL" />
      </geometry>
    </collision>
  </link>
  <link
    name="link_1">
    <inertial>
      <origin
        xyz="-0.25 0 5.5511E-17"
        rpy="0 0 0" />
      <mass
        value="2.7971" />
      <inertia
        ixx="0.0023493"
        ixy="6.9389E-18"
        ixz="1.035E-18"
        iyy="0.066522"
        iyz="1.6528E-19"
        izz="0.068685" />
    </inertial>
    <visual>
      <origin
        xyz="0 0 0"
        rpy="0 0 0" />
      <geometry>
        <mesh
          filename="package://arm3/meshes/link_1.STL" />
      </geometry>
      <material
        name="">
        <color
          rgba="0.89804 0.91765 0.92941 1" />
      </material>
    </visual>
    <collision>
      <origin
        xyz="0 0 0"
        rpy="0 0 0" />
      <geometry>
        <mesh
          filename="package://arm3/meshes/link_1.STL" />
      </geometry>
    </collision>
  </link>
  <joint
    name="joint_1"
    type="revolute">
    <origin
      xyz="0 0 0.035"
      rpy="0 0 0" />
    <parent
      link="base_link" />
    <child
      link="link_1" />
    <axis
      xyz="0 0 1" />
    <limit
      lower="-3.14"
      upper="3.14"
      effort="10"
      velocity="1" />
  </joint>
  <link
    name="link_2">
    <inertial>
      <origin
        xyz="-0.25 0 0"
        rpy="0 0 0" />
      <mass
        value="2.7971" />
      <inertia
        ixx="0.0023493"
        ixy="-1.7347E-18"
        ixz="2.1106E-18"
        iyy="0.066522"
        iyz="1.0371E-21"
        izz="0.068685" />
    </inertial>
    <visual>
      <origin
        xyz="0 0 0"
        rpy="0 0 0" />
      <geometry>
        <mesh
          filename="package://arm3/meshes/link_2.STL" />
      </geometry>
      <material
        name="">
        <color
          rgba="0.89804 0.91765 0.92941 1" />
      </material>
    </visual>
    <collision>
      <origin
        xyz="0 0 0"
        rpy="0 0 0" />
      <geometry>
        <mesh
          filename="package://arm3/meshes/link_2.STL" />
      </geometry>
    </collision>
  </link>
  <joint
    name="joint_2"
    type="revolute">
    <origin
      xyz="-0.5 0 0.02"
      rpy="0 0 0" />
    <parent
      link="link_1" />
    <child
      link="link_2" />
    <axis
      xyz="0 0 -1" />
    <limit
      lower="-3.14"
      upper="3.14"
      effort="10"
      velocity="1" />
  </joint>
  <link
    name="gripper">
    <inertial>
      <origin
        xyz="-0.027599 5.5511E-17 0"
        rpy="0 0 0" />
      <mass
        value="0.51442" />
      <inertia
        ixx="0.00064182"
        ixy="-4.0658E-20"
        ixz="6.3414E-20"
        iyy="0.0009505"
        iyz="4.364E-21"
        izz="0.001558" />
    </inertial>
    <visual>
      <origin
        xyz="0 0 0"
        rpy="0 0 0" />
      <geometry>
        <mesh
          filename="package://arm3/meshes/gripper.STL" />
      </geometry>
      <material
        name="">
        <color
          rgba="0.89804 0.91765 0.92941 1" />
      </material>
    </visual>
    <collision>
      <origin
        xyz="0 0 0"
        rpy="0 0 0" />
      <geometry>
        <mesh
          filename="package://arm3/meshes/gripper.STL" />
      </geometry>
    </collision>
  </link>
  <joint
    name="joint_3"
    type="fixed">
    <origin
      xyz="-0.5 0 -0.02"
      rpy="0 0 0" />
    <parent
      link="link_2" />
    <child
      link="gripper" />
    <axis
      xyz="0 0 0" />
    <limit
      lower="-3.14"
      upper="3.14"
      effort="10"
      velocity="1" />
  </joint>
</robot>